Workbook

Sheet Instructions
A1: Digital Sovereignty Audit Framework (DSAF) — Operational Reversibility
A2: Technology Domain: Operational Reversibility | Exit Strategy and Reversibility | Version 1.1
A4: How to Use This Form
A5: This form can be used to assess whether an organization can exit its current cloud provider arrangement without catastrophic loss of continuity, data, or institutional knowledge. The guiding question from the DICTU Toetsingsinstrument (2026, criterion 3.4) is: 'Can a third party take over the service upon provider failure or contract termination, based on available documentation and design?' The EuroStack framework (2025, Criterion 2.3) adds: 'A contractually binding exit plan is mandatory.'
A6: The form covers all five control areas. The audit questions (the numbered Yes/No questions) are the starting point: they define what the auditor must verify. All five control areas are assessed on two dimensions: design maturity (whether the control is designed to achieve its objective) and operating effectiveness (whether the designed control actually operated as intended during the audit period).
A8: Part A: Design Maturity (M1–M5) | B8: Part B: Operating Effectiveness (E1–E4)
A9: Assesses whether the control is designed to achieve its objective. The question is: if this control operates exactly as written, would it mitigate the risk? | B9: Assesses whether the designed control operated as intended during the audit period. The question is: did the control work in practice?
A11: Framework Origin
A12: The five maturity levels in this form correspond directly to the five DICTU sovereignty levels for Criterion 3.4. The definitions below are reproduced verbatim. Source: DICTU Toetsingsinstrument Soevereiniteit Clouddiensten v1.0.1 (January 2026), p. 20.
A13: Although presented here in generic form, the definitions of these levels have been further specified per norm and subdimension in the remainder of this document, providing additional context to make them more relevant and applicable to each specific assessment area.
A14: The sovereignty dimensions, control objectives, and structure of this framework are derived from DICTU, relevant ISO standards, the EuroStack Buy European Framework, and broader sovereignty frameworks. These sources have been consolidated and operationalized into auditable control language tailored to IT auditing in the context of operational reversibility.
A15: Quantitative tresholds (e.g. Infrastructure-as-Code (IaC) coverage, review intervals) are design choices that make the quantitative DICTU maturity levels measurable.
A17: Step-by-Step Workflow
A18: Step 1 | B18: Read the control area. For each of the five control areas (C1-C5), read the Risk, Objective, and Sovereignty Link at the top of the sheet before starting the audit questions, to understand what is being tested and why.
A19: Step 2 | B19: Answer the Audit Questions. Work through the numbered Yes/No questions for that control area. These define the minimum evidence the auditor must request and review; they do not yet determine a score.
A20: Step 3 | B20: Score Part A (Design Maturity, M1-M5). Starting from M1, check whether ALL criteria at each level are satisfied, moving upward. Tick the HIGHEST level for which every cumulative criterion is met. Evidence listed is suggested, not mandatory; document your rationale if alternative evidence was used.
A21: Step 4 | B21: Score Part B (Operating Effectiveness, E1-E4). Independently of Part A, assess whether the control has actually been demonstrated in practice (tested, exercised, executed), not only designed. Part A and Part B scores are never averaged together.
A22: Step 5 | B22: Document the conclusion and ownership. Complete the Maturity/Effectiveness Level Assigned fields and the Rationale/Finding box, and identify the responsible role for follow-up using the Responsible Role table on each control sheet.
A23: Step 6 | B23: Repeat for all five control areas, then complete the Summary tab. Enter the assigned Design Maturity (M1-M5) and Operating Effectiveness (E1-E4) level for each control area; the average scores and decision-rule outcome are calculated automatically.
A24: Step 7 | B24: Record the overall conclusion. Use the Decision Rules on the Summary tab as guidance, document the basis for the overall conclusion, and list priority recommendations with named owners and deadlines.
A25: Note: a level applies only if every cumulative criterion at that level is satisfied. If evidence is missing, ambiguous, or the situation is atypical, apply professional judgement and document the rationale rather than forcing a score.
A27: Part A: Design Maturity (M1–M5)
A28: Level | B28: Designation | C28: Description
A29: M1 | B29: No Reversibility | C29: No reversibility: The service is not transferable; continuity in the event of provider failure is not guaranteed.
A30: M2 | B30: Limited Reversibility | C30: Limited reversibility: Documentation is available to a limited extent, but transferring to a third party is complex and not fully feasible.
A31: M3 | B31: Contractual Reversibility | C31: Contractual reversibility: The service is largely transferable; documentation and design are available at a high level to enable a third party to independently operate the service over time.
A32: M4 | B32: Active Reversibility | C32: Active reversibility: The service is fully transferable; documentation and design are sufficiently detailed to enable a third party to independently operate the service.
A33: M5 | B33: Full Operational Reversibility | C33: Full operational reversibility: The service is fully transferable; documentation and design are sufficiently detailed and tested to enable a third party to independently operate the service.
A35: Part B: Operational Effectiveness (E1–E4)
A36: Level | B36: Designation | C36: Description
A37: E1 | B37: Not Effective | C37: Control has never been tested or operated
A38: E2 | B38: Partially Effective | C38: Control exists but untested or incomplete
A39: E3 | B39: Largely Effective | C39: Control demonstrated with minor gaps
A40: E4 | B40: Fully Effective | C40: Control fully demonstrated and independently verified

Sheet Definitions
A1: Definitions and Key Terms
A2: Glossary of terms used in the Digital Sovereignty Audit Framework: Operational Reversibility
A4: Framework & Sources
A5: Digital Sovereignty Audit Framework (DSAF) | C5: The structured audit framework used in this workbook to assess whether an organisation can exit a cloud provider without catastrophic loss of continuity, data, or institutional knowledge. It covers five control areas, each scored on design and operating effectiveness.
A6: Operational Reversibility | C6: The capacity to transfer a cloud service to another provider (or bring it back in-house) in an orderly way, so continuity is maintained on provider failure or contract termination. The central theme this framework assesses.
A7: Digital Sovereignty | C7: The degree of control an organisation retains over its data, systems, and technology choices, including the ability to change provider without undue dependence. 'Technology Sovereignty' is the specific DICTU dimension (3.4) on reversibility.
A8: DICTU | C8: The Dutch government's shared ICT service organisation. Its assessment instrument for cloud sovereignty provides the maturity levels and criteria on which this framework is based.
A9: DICTU Toetsingsinstrument | C9: The DICTU 'Toetsingsinstrument Soevereiniteit Clouddiensten' (assessment instrument for cloud-service sovereignty). Criterion 3.4 and its five sovereignty levels underpin the design-maturity scale used here.
A10: EuroStack (Buy European Framework) | C10: A European framework promoting digital autonomy and use of European infrastructure. Its Criterion 2.3 ('a contractually binding exit plan is mandatory') is referenced as a sovereignty requirement in this framework.
A11: Sovereignty link | C11: The field at the top of each control sheet that maps the control to the underlying sovereignty requirement (e.g. DICTU 3.4, EuroStack 2.3), showing why the control matters.
A13: Assessment Structure
A14: Control area | C14: One of the five themes assessed (C1–C5): Exit Plan, Data Portability, Knowledge Transfer, Continuity of Operations, and Testing Programme. Each has its own sheet.
A15: Audit question | C15: A numbered Yes/No question (e.g. 1.1, 1.2) defining what the auditor must verify for a control. The starting point of the assessment.
A16: Design Effectiveness (Maturity) | C16: Whether a control is designed to achieve its objective: if it operated exactly as written, would it mitigate the risk? Scored on the M1–M5 maturity scale (Part A).
A17: Operating Effectiveness | C17: Whether the designed control actually operated as intended during the audit period: did it work in practice? Scored on the E1–E4 scale (Part B).
A18: Maturity level (M1–M5) | C18: The design-effectiveness rating. Levels are cumulative: a higher level requires all lower-level criteria to be met. The auditor ticks the highest fully satisfied level.
A19: Effectiveness level (E1–E4) | C19: The operating-effectiveness rating, from Not Effective (E1) to Fully Effective (E4), based on evidence that the control operated during the period.
A20: Cumulative | C20: A scoring principle: a given level can only be assigned if all criteria of every lower level are also satisfied.
A22: Maturity Levels (Design, Part A)
A23: M1: No Reversibility | C23: The service is not transferable; continuity on provider failure is not guaranteed.
A24: M2: Limited Reversibility | C24: Documentation exists to a limited extent, but transfer to a third party is complex and not fully feasible.
A25: M3: Contractual Reversibility | C25: The service is largely transferable; documentation and design are available at a high level for a third party to operate it over time.
A26: M4: Active Reversibility | C26: The service is fully transferable; documentation and design are detailed enough for a third party to operate it independently.
A27: M5: Full Operational Reversibility | C27: As M4, and the documentation and design have been tested, confirming a third party can independently operate the service.
A29: Effectiveness Levels (Operating, Part B)
A30: E1: Not Effective | C30: The control has never been tested or operated; evidence of operation is absent.
A31: E2: Partially Effective | C31: The control exists but is untested or incomplete in operation.
A32: E3: Largely Effective | C32: The control has been demonstrated to operate, with only minor gaps.
A33: E4: Fully Effective | C33: The control is fully demonstrated and independently verified.
A35: Exit & Continuity
A36: Exit plan | C36: A formally approved, contractually supported plan enabling an orderly transition to an alternative provider within a defined RTO. The prerequisite control (C1).
A37: Vendor lock-in | C37: Dependence on a single provider that makes leaving prohibitively difficult or costly. Without an exit plan it is a certain outcome rather than a risk.
A38: RTO (Recovery Time Objective) | C38: The maximum acceptable time to restore the service with an alternative provider in an exit scenario; should be formally defined and approved.
A39: Rollback | C39: A defined procedure to revert to the original provider or state if a migration fails, including trigger criteria and execution steps.
A40: Parallel operation period | C40: A phase during migration in which old and new environments run simultaneously to safeguard continuity before cut-over.
A41: Business Impact Analysis (BIA) | C41: An assessment of how critical a service is to the organisation, used to validate that the RTO matches the service's importance.
A42: Service Level Agreement (SLA) | C42: The contracted service performance levels; cross-checked to ensure continuity and degradation tolerance are maintained during migration.
A43: Service degradation tolerance | C43: The level of reduced service the organisation can accept during a migration, defined per service and validated against SLAs.
A45: Data & Technical Portability
A46: Data portability | C46: The ability to export data and workloads to another environment without significant effort, cost, or loss, ideally in open formats.
...

Sheet C1
A1: Control 1: Exit plan and contractual exit framework
A2: Risk | C2: Without a formal exit plan the organization is structurally dependent on the current provider. In the event of forced exit, insolvency, geopolitical sanctions, acquisition by a non-EU entity, the absence of a plan results in operational crisis, uncontrollable data loss, or contractual imprisonment. Vendor lock-in is not a risk in this scenario but a certain outcome.
A3: Objective | C3: Verify that a formally approved, contractually supported exit plan exists enabling an orderly transition to an alternative provider within a defined Recovery Time Objective (RTO).
A4: Sovereignty link | C4: Technology Sovereignty (DICTU 3.4) | EuroStack Criterion 2.3: 'A contractually binding exit plan is mandatory' | Guiding question: 'Can a third party take over the service upon provider failure or contract termination?'
A6: Audit Questions
A7: # | C7: Audit Question | D7: Yes/No | E7: Notes
A8: 1.1 | C8: Does a formally approved, version-controlled exit plan document exist for this cloud service?
A9: 1.2 | C9: Does the cloud service contract contain explicit exit rights, including data export rights, provider transition assistance obligation, and absence of punitive egress fees at termination?
A10: 1.3 | C10: Is a Recovery Time Objective (RTO) for the exit scenario formally defined and approved by the CIO or equivalent authority?
A11: 1.4 | C11: Does the exit plan identify at least two credible alternative providers (including at least one EU-domiciled alternative) with a documented compatibility assessment?
A12: 1.5 | C12: Does the exit plan have a named owner (by role), a defined review cycle, and evidence of at least one review within the past 24 months?
A14: Part A: Design Maturity (M1–M5)
A15: Instructions: Tick (✓) the HIGHEST level at which ALL criteria are fully satisfied. Levels are CUMULATIVE.
A16: Level | C16: Definition | D16: Criteria (cumulative) | E16: Suggested Evidence to Provide | F16: Reached (✓) | G16: Notes
A17: M1 | B17: No Reversibility | C17: Service not transferable; continuity upon provider failure not guaranteed. | D17: 1. No exit plan exists in any form. 2. No contractual exit rights in the service agreement. 3. No consideration has been given to what happens if the provider fails. | E17: → Absence of a named exit plan document confirms M1. If no evidence is produced, this level applies by default.
A18: M2 | B18: Limited Reversibility | C18: Documentation is limited; transfer to a third party is complex and not fully possible. | D18: 1. Cumulative: the organization has progressed beyond M1 (the M1 absence conditions no longer apply), PLUS: 2. An exit plan document exists in some form (draft, informal note, or process document). 3. The plan is significantly outdated (more than 24 months without review) or lacks formal approval. 4. Contractual exit rights are absent or contain terms that make exit economically prohibitive. | E18: → Exit plan document (draft or otherwise); note: outdated or unapproved plans confirm M2. → Contract text showing absence of exit rights or presence of prohibitive exit fees.
A19: M3 | B19: Contractual Reversibility | C19: Service largely transferable; high-level documentation available for a third party to operate the service in due course. | D19: 1. Cumulative: all M2 criteria satisfied, PLUS: 2. Exit plan is formally approved by an appropriate authority (minimum: IT Director or CIO). 3. Contract contains explicit exit rights including data export right, no punitive egress fees, and minimum transition assistance obligation. 4. RTO for the exit scenario is defined (though may not yet be tested or validated). | E19: → Exit plan with approval record, dated within 24 months. → Contract or DPA section confirming explicit exit rights and no punitive egress fees. → RTO definition document or section in exit plan approved by CIO.
A20: M4 | B20: Active Reversibility | C20: Service fully transferable; documentation sufficiently detailed for a third party to operate the service independently. | D20: 1. Cumulative: all M3 criteria satisfied, PLUS: 2. Exit plan is detailed and current (reviewed within 12 months), containing: migration phases, phase-gate criteria, parallel operation period, data synchronization approach, and rollback trigger conditions. 3. At least two credible alternatives identified with compatibility assessment; at least one EU-domiciled alternative. 4. Named owner by role; formal review cycle defined and evidenced. 5. RTO has been validated against the business impact analysis of the relevant cloud service. | E20: → Exit plan with review date within 12 months, phase diagram, and gate criteria. → Alternative provider assessment document with EU jurisdiction confirmation. → Business Impact Analysis linking RTO to criticality of service. → Owner assignment and review cycle record.
A21: M5 | B21: Full Operational Reversibility | C21: Service fully transferable; documentation sufficiently detailed and tested for a third party to operate independently. | D21: 1. Cumulative: all M4 criteria satisfied, PLUS: 2. Exit plan has been validated through at least a structured tabletop exercise simulating an unplanned exit trigger (provider insolvency, sanctions, or non-EU acquisition). 3. At least one alternative provider is pre-qualified or has a contract on standby. 4. Exit plan and RTO reviewed or independently assessed within 12 months. | E21: → Tabletop exercise report: date, scenario (must include unplanned trigger), participants, findings, remediation. → Pre-qualification documentation or standby contract with alternative EU provider. → Independent review or internal audit report on exit plan adequacy.
A22: DESIGN MATURITY CONCLUSION | C22: Maturity Level Assigned: | D22: {=IFERROR(LOOKUP(2,1/(F17:F21<>""),{1;2;3;4;5}),"")} | E22: Rationale / Finding:
A24: Part B: Operational Effectiveness (E1–E4)
A25: Instructions: Assess whether the designed control operated as intended during the audit period.
B26: Level | C26: What the Organization Must Demonstrate | D26: Audit Procedure | E26: Audit Guidance | F26: Reached (✓) | G26: Notes
A27: E1 | B27: Not Effective | C27: 1. Exit plan exists on paper only. 2. Plan has never been operationally referenced or tested. 3. Contractual exit rights unverified. | D27: 1. Inspect exit plan currency and formal approval. 2. Interview exit plan owner: can they explain the plan without looking at it? 3. Check contract for exit rights clause. | E27: If the exit plan has not been reviewed in 24 months or key stakeholders are unaware of it, rate E1 regardless of maturity score.
A28: E2 | B28: Partially Effective | C28: 1. Exit plan reviewed within 24 months. 2. Contractual exit rights confirmed current. 3. RTO approved by CIO. 4. Alternative providers identified. | D28: 1. Review evidence of last plan update and approval. 2. Confirm contractual exit rights are still valid. 3. Interview exit plan owner on RTO rationale and plan awareness. | E28: Plan is maintained but has never been tested. This is the most common state. Document as observation and recommend tabletop exercise as priority action.
A29: E3 | B29: Largely Effective | C29: 1. Exit plan reviewed within 12 months. 2. Tabletop exercise conducted within 24 months. 3. Findings from exercise addressed and documented. | D29: 1. Review tabletop exercise report: scope, scenario, participants, findings. 2. Verify findings register and confirm all items are closed or on schedule. 3. Confirm scenario included an unplanned trigger; planned migration only is insufficient for E3. | E29: E3 requires evidence that the plan has been stress-tested, not only maintained. Unplanned triggers must feature in the scenario.
A30: E4 | B30: Fully Effective | C30: 1. Exit plan tested via live exercise or partial migration. 2. Alternative provider pre-qualified or contracted on standby. 3. All prior exercise findings closed. | D30: 1. Review live exercise documentation or partial migration test evidence. 2. Verify pre-qualification or standby contract with alternative EU provider. 3. Confirm all findings from prior exercises are closed. | E30: E4 requires demonstrated exit capability, proof of execution, not intent. An organization that has only conducted tabletop exercises but no live test is at most E3.
A31: OPERATING EFFECTIVENESS CONCLUSION | C31: Effectiveness Level Assigned: | D31: {=IFERROR(LOOKUP(2,1/(F27:F30<>""),{1;2;3;4}),"")} | E31: Rationale / Finding:
A33: Responsible Roles
A34: Design Maturity Level | C34: Responsible Role (typically accountable for evidence at this level)
A35: M1–M2 | C35: No named owner exists at this level (criteria reflect absence). Escalate to IT Director / CIO to initiate an exit plan.
A36: M3 | C36: IT Director or CIO: approves the exit plan and the RTO (minimum approval authority per criteria).
A37: M4 | C37: Named exit plan owner (by role) + CIO: owner maintains the plan and review cycle; CIO validates RTO against business impact analysis.
A38: M5 | C38: Named exit plan owner + CIO + Internal Audit: exercise participants per the tabletop scenario; Internal Audit performs the independent review.
A40: Operating Effectiveness Level | C40: Responsible Role (typically accountable for evidence at this level)
A41: E1 | C41: Exit plan owner (if named): interviewed to assess awareness; escalate to CIO if plan is unreviewed beyond 24 months.
A42: E2 | C42: Exit plan owner: accountable for plan currency and RTO awareness.
A43: E3 | C43: Exit plan owner + tabletop exercise participants (IT, Legal, Compliance as applicable): accountable for findings remediation.
A44: E4 | C44: Exit plan owner + CIO: CIO confirms pre-qualification/standby contract; owner closes prior findings.

Sheet C2
A1: Control 2: Data Portability and Technical Exportability
A2: Risk | C2: If data cannot be exported in a usable format, exit is technically impossible even when contractually permitted. Proprietary formats, excessive egress fees, and missing export tooling create a 'data gravity trap'. EuroStack (2025) identifies punitive egress fees as 'strategic barriers that prevent a competitive European market.'
A3: Objective | C3: Verify that all data, primary data, backups, configurations, metadata, and logs, can be exported at any time in open, non-proprietary formats at proportionate cost, and that export procedures are documented and tested.
A4: Sovereignty link | C4: Technology Sovereignty (DICTU 3.1, Interoperability & Portability) | EuroStack Criterion 2.1 (data portability, no punitive egress fees) | GDPR Art. 20 (personal data portability)
A6: Audit Questions
A7: # | C7: Audit Question | D7: Yes/No | E7: Notes
A8: 2.1 | C8: Can the organization demonstrate that all primary production data types can be exported in open, non-proprietary formats (e.g. CSV, JSON, Parquet, XML, OVA/OVF) without requiring provider-specific tooling to read the output?
A9: 2.2 | C9: Does the cloud service contract explicitly prohibit punitive egress fees at contract termination, and does the cost modelling for exporting current data volumes at termination confirm fees are proportionate to actual transfer costs?
A10: 2.3 | C10: Are Infrastructure-as-Code (IaC) artefacts for all production infrastructure stored in an organization-controlled version control repository, not solely in provider-managed systems?
A11: 2.4 | C11: Are backup copies and disaster recovery replicas exportable with the same open format and portability standard as primary data, and is this verified through separate backup export testing?
A12: 2.5 | C12: Has the organization conducted an end-to-end export test, including import validation in an alternative environment, for all primary data types within the past 24 months?
A14: Part A: Design Maturity (M1–M5)
A15: Instructions: Tick (✓) the HIGHEST level at which ALL criteria are fully satisfied. Levels are CUMULATIVE.
A16: Level | C16: Definition | D16: Criteria (cumulative) | E16: Suggested Evidence to Provide | F16: Reached (✓) | G16: Notes
A17: M1 | B17: No Portability | C17: Service fully proprietary; migration of data and workloads not possible without significant effort or cost. | D17: 1. Data stored exclusively in proprietary provider formats with no open export mechanism. 2. Egress fees are prohibitive, or the organization has not assessed the termination cost. 3. No IaC exists; infrastructure configurations are undocumented or stored only in provider consoles. | E17: → Provider documentation showing only proprietary formats, or the organization cannot provide any export format specification.
A18: M2 | B18: Limited Portability | C18: Partial openness; migration is limited and requires significant effort. | D18: 1. Cumulative: the organization has progressed beyond M1 (the M1 absence conditions no longer apply), PLUS: 2. Export is possible for at least some data types but requires significant provider involvement or re-formatting effort. 3. Some core data types remain in proprietary formats. 4. Egress fees have been reviewed but not modelled for a full exit scenario. | E18: → Contract or DPA section listing available export formats. → Data inventory showing which data types have open export and which do not.
A19: M3 | B19: Open Standards Partial | C19: Open standards widely used but not for all components; portability partially limited. | D19: 1. Cumulative: M2 satisfied, PLUS: 2. All primary data types have a documented open format export option. 3. Contract confirms no punitive egress fees at termination. 4. IaC covers at least 50% of production infrastructure components in organization-controlled repositories. 5. Backup export format has been assessed, even if not yet tested. | E19: → Export format specification per data type (contract or technical documentation). → Contract clause confirming absence of punitive egress fees. → IaC repository location and ownership evidence with coverage percentage estimate.
A20: M4 | B20: All Open Standards | C20: All components use open standards; high portability, not yet fully optimized. | D20: 1. Cumulative: M3 satisfied, PLUS: 2. IaC coverage exceeds 80% of all production infrastructure components. 3. Export test conducted for all primary data types within 24 months, confirming successful export without provider tooling. 4. Backup and DR replicas confirmed to use the same open format and portability standard as primary data. 5. Data egress cost modelled for a realistic full-exit scenario confirming proportionality. | E20: → IaC coverage report confirming more than 80% (spot-check by auditor recommended). → Export test results per data type, dated within 24 months. → Backup export test evidence or configuration confirming same standard. → Egress cost model for full exit scenario.
A21: M5 | B21: Maximum Portability | C21: Most widely used open standards; maximized portability; migration easy and cost-efficient. | D21: 1. Cumulative: M4 satisfied, PLUS: 2. Full end-to-end export test completed: all data types, backups, metadata, IaC configurations, and logs. 3. Import validation in an alternative environment confirms no data loss and readability without provider tooling. 4. Results independently reviewed or included in internal audit scope. | E21: → Full export test report including all data types, backups, configs, logs. → Import validation evidence in alternative environment (not just export success). → Independent review record or internal audit finding on portability controls.
A22: DESIGN MATURITY CONCLUSION | C22: Maturity Level Assigned: | D22: {=IFERROR(LOOKUP(2,1/(F17:F21<>""),{1;2;3;4;5}),"")} | E22: Rationale / Finding:
A24: Part B: Operational Effectiveness (E1–E4)
A25: Instructions: Assess whether the designed control operated as intended during the audit period.
A26: Level | C26: What the Organization Must Demonstrate | D26: Audit Procedure | E26: Audit Guidance | F26: Reached (✓) | G26: Notes
A27: E1 | B27: Not Effective | C27: 1. Export has never been tested for any data type. 2. Organization cannot identify data format in use. 3. Egress fees at termination have not been reviewed. | D27: 1. Request list of data types and their export formats. 2. Attempt walkthrough of export for one minor data type. 3. Review contract for egress fee structure. | E27: If no export test has been conducted and the organization cannot explain what format their data is in, rate E1 regardless of contractual claims.
A28: E2 | B28: Partially Effective | C28: 1. Primary data types confirmed in open format. 2. Some export tests conducted but coverage is incomplete. 3. IaC repository ownership confirmed. | D28: 1. Review available export test results and note which types are missing. 2. Confirm IaC repository is organization-controlled. 3. Review contract egress fee clause. | E28: Partial test coverage does not constitute demonstrated portability. Metadata and logs are frequently the untested gap.
A29: E3 | B29: Largely Effective | C29: 1. All primary data types tested for export. 2. Export duration validated against RTO. 3. Backup portability confirmed. | D29: 1. Review export test results for all data types. 2. Verify duration is within RTO. 3. Perform readability test: attempt to open or parse one exported file using a non-provider tool. | E29: E3 requires that exported data has been validated as usable, not only that export completed. A file that exports but cannot be opened in a standard tool is a finding.
A30: E4 | B30: Fully Effective | C30: 1. Full end-to-end export test: all types, backups, IaC, logs. 2. Import validation in alternative environment confirms no data loss. 3. Independent review of portability controls. | D30: 1. Review full export test report. 2. Confirm import validation in alternative environment (must include at least one critical data type imported and validated). 3. Review independent assessment scope. | E30: E4 requires import validation in a target environment. 'Export ran successfully' without import validation is at most E3.
A31: EFFECTIVENESS CONCLUSION | C31: Effectiveness Level Assigned: | D31: {=IFERROR(LOOKUP(2,1/(F27:F30<>""),{1;2;3;4}),"")} | E31: Rationale / Finding:
A33: Responsible Roles
A34: Design Maturity Level | C34: Responsible Role (typically accountable for evidence at this level)
A35: M1–M2 | C35: No named owner exists at this level. Escalate to Infrastructure/Platform Lead to assess export and IaC posture.
A36: M3 | C36: Infrastructure/Platform Lead: owns IaC repository and data export format documentation (>50% coverage).
A37: M4 | C37: Infrastructure/Platform Lead + Data Owner: Infrastructure Lead delivers IaC coverage >80% and export tests; Data Owner confirms backup/DR parity.
A38: M5 | C38: Infrastructure/Platform Lead + Internal Audit: Infrastructure Lead executes full export/import test; Internal Audit reviews results.
A40: Operating Effectiveness Level | C40: Responsible Role (typically accountable for evidence at this level)
A41: E1 | C41: Infrastructure/Platform Lead: accountable for identifying data formats in use.
A42: E2 | C42: Infrastructure/Platform Lead: accountable for closing untested data types (commonly metadata/logs).
A43: E3 | C43: Infrastructure/Platform Lead: accountable for RTO-aligned export duration and readability testing.
A44: E4 | C44: Infrastructure/Platform Lead + Internal Audit: Internal Audit reviews import validation evidence.

Sheet C3
A1: Control 3: Knowledge Transfer and Operational Documentation
A2: Risk | C2: Tacit knowledge held by a small number of key employees or embedded in provider-specific tooling creates human lock-in as dangerous as technical lock-in. When these people leave, or the provider's specialist knowledge is withdrawn at termination, the organization loses operational capability regardless of data portability.
A3: Objective | C3: Verify that the cloud environment is documented in sufficient detail for a competent but previously uninvolved third party to assume full operational control within the exit RTO, without requiring knowledge transfer from provider personnel.
A4: Sovereignty link | C4: Technology Sovereignty (DICTU 3.4 levels 4–5: documentation 'sufficiently detailed for a third party to operate the service independently') | EuroStack Criterion 2.3 | DICTU 5.5.2 (capacity and skills)
A6: Audit Questions
A7: # | C7: Audit Question | D7: Yes/No | E7: Notes
A8: 3.1 | C8: Is the system architecture documented in a current, version-controlled document (reviewed within 12 months) covering: network topology, data flows, integration points, component dependencies, and security architecture, stored in an organization-controlled system?
A9: 3.2 | C9: Does Infrastructure-as-Code (IaC) cover at least 80% of all production infrastructure components, with artefacts stored in an organization-managed repository and a recent IaC-based deployment confirming the IaC is functional (not merely present)?
A10: 3.3 | C10: Has the organization conducted a key person dependency analysis, identified all cloud functions relying on fewer than two individuals, and established a documented remediation plan for each identified dependency?
A11: 3.4 | C11: Are operational runbooks available for all routine and non-routine procedures (deployment, scaling, backup, recovery, incident response) in sufficient detail for a competent engineer unfamiliar with the environment to execute them?
A12: 3.5 | C12: Has the documentation been tested by a party external to the current team, confirming that a competent engineer unfamiliar with the environment can successfully execute a deployment or operational procedure using only the available documentation?
A14: Part A: Design Maturity (M1–M5)
A15: Instructions: Tick (✓) the HIGHEST level at which ALL criteria are fully satisfied. Levels are CUMULATIVE.
A16: Level | C16: Definition | D16: Criteria (cumulative) | E16: Suggested Evidence to Provide | F16: Reached (✓) | G16: Notes
A17: M1 | B17: No Documentation | C17: Service not transferable; continuity not guaranteed | D17: 1. No current architecture documentation exists. 2. Operations depend entirely on knowledge held by one or two individuals or on provider specialist assistance. 3. IaC coverage below 20%; most infrastructure is manually configured. | E17: → Absence of documentation confirms M1. If the organization cannot produce an architecture document reviewed within 36 months, M1 applies.
A18: M2 | B18: Limited Documentation | C18: Documentation limited; transfer to third party complex and not fully possible. | D18: 1. Cumulative: the organization has progressed beyond M1 (the M1 absence conditions no longer apply), PLUS: 2. Some documentation exists but is significantly outdated (not reviewed in 24 or more months) or covers only parts of the environment. 3. Multiple key person dependencies exist without a remediation plan. 4. IaC coverage between 20 and 50%. | E18: → Architecture document (note: outdated or incomplete documents confirm M2 ceiling). → Key person analysis showing unaddressed single-person dependencies.
A19: M3 | B19: Basic Documentation | C19: Service largely transferable; high-level documentation available. | D19: 1. Cumulative: M2 satisfied, PLUS: 2. Architecture document is current (reviewed within 24 months) and covers main components. 3. Basic operational runbooks exist for primary procedures. 4. IaC coverage exceeds 50%. 5. Key persons have been identified and at least partial cross-training is underway. | E19: → Architecture document with review date within 24 months. → Runbook list for primary procedures. → IaC repository with coverage estimate above 50%. → Key person analysis with cross-training progress record.
A20: M4 | B20: Sufficient Documentation | C20: Service fully transferable; documentation sufficiently detailed for a third party to operate independently. | D20: 1. Cumulative: M3 satisfied, PLUS: 2. Architecture document current (reviewed within 12 months) and comprehensive, covering all components including integrations, security controls, and recovery procedures. 3. IaC coverage exceeds 80%; recent deployment from IaC confirms it is functional. 4. All routine and non-routine procedures are in runbooks. 5. No unaddressed critical single-person dependencies remain. | E20: → Architecture document review date within 12 months; comprehensive scope confirmed. → IaC coverage evidence above 80%; recent IaC-based deployment log as proof of function. → Runbook index covering all procedures (routine, incident, and disaster recovery). → Key person analysis with all critical dependencies addressed.
A21: M5 | B21: Comprehensive Documentation | C21: Service fully transferable; documentation sufficiently detailed and tested. | D21: 1. Cumulative: M4 satisfied, PLUS: 2. Documentation tested by a party outside the current team: a competent engineer unfamiliar with the environment successfully executed at least one deployment or operational procedure using only the available documentation. 3. Test result is documented with: date, tester (not an author of the documentation), procedure executed, and outcome. | E21: → Documentation test report: tester name and role (must not be an author), date, procedure executed, outcome. → Confirmation that tester had no prior knowledge of the specific environment. → IaC deployment log from the test run.
A22: DESIGN MATURITY CONCLUSION | C22: Maturity Level Assigned: | D22: {=IFERROR(LOOKUP(2,1/(F17:F21<>""),{1;2;3;4;5}),"")} | E22: Rationale / Finding:
A24: Part B: Operational Effectiveness (E1–E4)
A25: Instructions: Assess whether the designed control operated as intended during the audit period.
A26: Level | C26: What the Organization Must Demonstrate | D26: Audit Procedure | E26: Audit Guidance | F26: Reached (✓) | G26: Notes
A27: E1 | B27: Not Effective | C27: 1. Architecture documentation significantly outdated or absent. 2. Key person dependencies unaddressed. 3. IaC below 50%. | D27: 1. Inspect architecture document version date. 2. Request IaC repository and spot-check coverage. 3. Ask two non-primary cloud engineers to explain the architecture; if they cannot, documentation is insufficient. | E27: Practical test: ask a senior team member who is not the primary cloud engineer to locate and describe the data flow for a named application. Inability to do so without the primary engineer is a clear E1 indicator.
A28: E2 | B28: Partially Effective | C28: 1. Documentation current. 2. IaC present with known coverage. 3. Key persons identified with remediation in progress. | D28: 1. Review IaC coverage via repository spot-check; do not accept stated coverage without verification. 2. Verify architecture document review date. 3. Review key person analysis and cross-training records for progress. | E28: IaC coverage claims must be verified by actually opening the repository and checking, not accepted on assertion. 'We have Terraform scripts' is not evidence of 80% coverage.
A29: E3 | B29: Largely Effective | C29: 1. IaC above 80% confirmed. 2. Runbooks cover all critical procedures. 3. No critical single-person dependencies remaining. | D29: 1. Verify IaC coverage against infrastructure inventory (sample five components). 2. Select three non-routine procedures and verify runbooks exist, are complete, and current. 3. Confirm key person analysis shows no open critical dependencies. | E29: Test documentation completeness: select one infrastructure component and walk through the IaC deployment with a team member who is not the author. Can they execute it? If not, E2 at best.
A30: E4 | B30: Fully Effective | C30: 1. Documentation tested by external or non-authoring party. 2. Deployment successfully executed using only documentation. 3. Test result documented with independence confirmed. | D30: 1. Review documentation test report, confirm tester is not an author. 2. Verify deployment log from the test run. 3. Confirm tester had no prior knowledge of the specific environment. | E30: The independence test is the defining criterion for E4: the person who executed the test must not be the person who wrote the documentation. Verify this explicitly.
A31: EFFECTIVENESS CONCLUSION | C31: Effectiveness Level Assigned: | D31: {=IFERROR(LOOKUP(2,1/(F27:F30<>""),{1;2;3;4}),"")} | E31: Rationale / Finding:
A33: Responsible Roles
A34: Design Maturity Level | C34: Responsible Role (typically accountable for evidence at this level)
A35: M1–M2 | C35: No remediation owner exists at this level. Escalate to Operations Lead to initiate documentation and key-person remediation.
A36: M3 | C36: Operations Lead: owns architecture documentation currency and cross-training progress for key persons.
A37: M4 | C37: Operations Lead + Engineering Manager: Operations Lead maintains comprehensive documentation and runbooks; Engineering Manager closes critical single-person dependencies.
A38: M5 | C38: Operations Lead + independent/non-authoring tester: tester (not a documentation author) executes the independence test; Operations Lead records the outcome.
A40: Operating Effectiveness Level | C40: Responsible Role (typically accountable for evidence at this level)
A41: E1 | C41: Operations Lead: accountable for architecture currency; a non-primary engineer is interviewed for the practical test.
A42: E2 | C42: Operations Lead: accountable for verified (not asserted) IaC coverage and cross-training records.
A43: E3 | C43: Operations Lead: accountable for runbook completeness and closure of critical dependencies (sample-verified).
A44: E4 | C44: Independent/non-authoring tester + Operations Lead: tester executes the deployment; Operations Lead confirms tester independence.

Sheet C4
A1: Control 4: Continuity of Operations During Migration
A2: Risk | C2: Even when exit plan, portability, and documentation are all adequate, the transition period is a high-risk window: services are partially operational, data is split across old and new environments, and teams must manage both simultaneously. Without a migration continuity plan, exit can trigger a service availability crisis that forces the organization to abort the migration.
A3: Objective | C3: Verify that the exit plan contains a migration continuity plan addressing: migration phases, parallel operation periods, data synchronization protocol, service degradation tolerance, rollback procedure with trigger criteria, and stakeholder communication.
A4: Sovereignty link | C4: Operational Sovereignty (DICTU 4 Operational) | NIS2 Art. 21 (business continuity) | DORA Art. 11 (ICT continuity policy) | ISO 22301 §8.5
A6: Audit Questions
A7: # | C7: Audit Question | D7: Yes/No | E7: Notes
A8: 4.1 | C8: Does the exit plan contain a dedicated migration continuity section with: defined migration phases, services operational at each phase, parallel operation period, data synchronization protocol, and explicit phase-gate criteria for cut-over?
A9: 4.2 | C9: Is there a documented data synchronization and integrity protocol specifying: synchronization frequency during migration, integrity check method, change-freeze or dual-write period, and a post-cut-over validation procedure?
A10: 4.3 | C10: Does the continuity plan contain a documented rollback procedure with explicit trigger criteria (conditions that activate rollback), step-by-step execution instructions, and an approved rollback RTO?
A11: 4.4 | C11: Has the service degradation tolerance for each cloud-hosted service been defined (e.g. read-only mode acceptable for x hours) and validated against contractual SLA obligations and any applicable NIS2 or DORA requirements?
A12: 4.5 | C12: Does the exit plan include a stakeholder communication plan for the migration period covering: internal stakeholders (IT, Legal, Risk, Board), external stakeholders (customers, supervisors), communication frequency, and escalation path for migration failures?
A14: Part A: Design Maturity (M1–M5)
A15: Instructions: Tick (✓) the HIGHEST level at which ALL criteria are fully satisfied. Levels are CUMULATIVE.
A16: Level | C16: Definition | D16: Criteria (cumulative) | E16: Suggested Evidence to Provide | F16: Reached (✓) | G16: Notes
A17: M1 | B17: No Continuity Plan | C17: No reversibility; continuity not guaranteed. | D17: 1. Exit plan contains no continuity section for the migration period. 2. No rollback procedure defined. 3. Service degradation tolerance undefined. | E17: → Absence of continuity section in exit plan confirms M1 for this control.
A18: M2 | B18: Continuity Acknowledged | C18: Limited reversibility; transfer is complex. | D18: 1. Cumulative: the organization has progressed beyond M1 (the M1 absence conditions no longer apply), PLUS: 2. Migration continuity is acknowledged as a risk in the exit plan but no detailed plan exists. 3. Rollback is mentioned but not procedurally defined (no trigger criteria, no execution steps). 4. Service degradation not formally assessed. | E18: → Exit plan section acknowledging continuity risk. → High-level rollback mention without procedure details.
A19: M3 | B19: Basic Plan Defined | C19: Service largely transferable; high-level documentation available. | D19: 1. Cumulative: M2 satisfied, PLUS: 2. Migration phases are defined with a phase diagram. 3. Parallel operation period is specified. 4. Data synchronization protocol described at high level. 5. Rollback procedure documented with trigger criteria, even if not yet tested. | E19: → Phase diagram in exit plan. → Parallel operation period specification. → Data synchronization protocol (can be at high level for M3). → Rollback procedure with trigger criteria.
A20: M4 | B20: Detailed and Validated Plan | C20: Service fully transferable; documentation sufficiently detailed. | D20: 1. Cumulative: M3 satisfied, PLUS: 2. Data synchronization protocol is detailed (specifying frequency, integrity check method, dual-write or freeze period). 3. Service degradation tolerance formally defined per service and validated against SLAs. 4. Rollback RTO approved by CIO or equivalent. 5. Communication plan completed identifying all stakeholders, channels, and escalation path. | E20: → Detailed synchronization protocol with integrity check procedure. → Service degradation tolerance document cross-referenced to SLA schedules. → Rollback RTO with CIO approval record. → Communication plan with stakeholder list reviewed by all named parties.
A21: M5 | B21: Tested Continuity Plan | C21: Service fully transferable; documentation sufficiently detailed and tested. | D21: 1. Cumulative: M4 satisfied, PLUS: 2. Migration continuity plan validated in a structured exercise; minimum: tabletop with an unplanned trigger scenario. 3. Rollback procedure explicitly tested in the exercise (rollback was activated as part of the scenario). 4. Exercise findings documented and remediated. | E21: → Exercise report with unplanned exit trigger scenario (not only voluntary migration). → Confirmation that rollback was activated and executed in the exercise. → Findings register with all exercise findings closed or on schedule.
A22: DESIGN MATURITY CONCLUSION | C22: Maturity Level Assigned: | D22: {=IFERROR(LOOKUP(2,1/(F17:F21<>""),{1;2;3;4;5}),"")} | E22: Rationale / Finding:
A24: Part B: Operational Effectiveness (E1–E4)
A25: Instructions: Assess whether the designed control operated as intended during the audit period.
A26: Level | C26: What the Organization Must Demonstrate | D26: Audit Procedure | E26: Audit Guidance | F26: Reached (✓) | G26: Notes
A27: E1 | B27: Not Effective | C27: 1. No continuity section in exit plan. 2. No rollback procedure. 3. Service degradation tolerance not defined. | D27: 1. Review exit plan for continuity section. 2. Verify rollback procedure exists. 3. Check SLA schedules for degradation tolerance. | E27: If exit plan has no continuity section, rate E1 for Control 4. This automatically limits the overall conclusion to at most partially effective.
A28: E2 | B28: Partially Effective | C28: 1. Continuity plan reviewed within 24 months. 2. Rollback procedure documented. 3. SLA cross-check performed. | D28: 1. Review continuity section currency. 2. Interview continuity plan owner on rollback trigger logic. 3. Verify SLA cross-check evidence. | E28: Plan exists and maintained but never tested. The most common state. Priority recommendation: schedule a tabletop exercise with an unplanned scenario.
A29: E3 | B29: Largely Effective | C29: 1. Tabletop exercise conducted with unplanned exit trigger. 2. Rollback explicitly tested in exercise. 3. Findings remediated. | D29: 1. Review exercise report; confirm scenario included unplanned trigger. 2. Verify rollback was activated (not merely discussed) in exercise. 3. Confirm findings closure. | E29: E3 requires that rollback was actually activated and tested in the exercise, not only that the scenario mentions rollback as an option. An exercise where rollback was discussed but not executed is E2.
A30: E4 | B30: Fully Effective | C30: 1. Partial migration test conducted with service continuity maintained throughout. 2. Rollback executed and confirmed functional. 3. Communication plan tested with actual stakeholders. | D30: 1. Review partial migration test documentation. 2. Verify rollback was executed and services resumed without data loss. 3. Confirm stakeholder communication test evidence. | E30: E4 requires actual partial migration execution. A tabletop simulation, however thorough, does not constitute E4 for this control.
A31: EFFECTIVENESS CONCLUSION | C31: Effectiveness Level Assigned: | D31: {=IFERROR(LOOKUP(2,1/(F27:F30<>""),{1;2;3;4}),"")} | E31: Rationale / Finding:
A34: Responsible Roles
A35: Design Maturity Level | C35: Responsible Role (typically accountable for evidence at this level)
A36: M1–M2 | C36: No continuity owner exists at this level. Escalate to Exit Plan Owner / CIO to initiate a migration continuity section.
A37: M3 | C37: Exit Plan Owner + Infrastructure Lead: define migration phases, parallel-operation period, and rollback trigger criteria.
A38: M4 | C38: Exit Plan Owner + CIO: CIO approves rollback RTO and degradation tolerance vs. SLA; Owner completes the stakeholder communication plan.
A39: M5 | C39: Exit Plan Owner + exercise participants (IT, Legal, Risk, Board as applicable): exercise rollback under an unplanned trigger scenario.
A41: Operating Effectiveness Level | C41: Responsible Role (typically accountable for evidence at this level)
A42: E1 | C42: Exit Plan Owner: accountable for the existence of a continuity section; absence caps the overall conclusion (Rule 1 / Summary tab).
A43: E2 | C43: Exit Plan Owner: accountable for continuity plan currency and SLA cross-check.
A44: E3 | C44: Exit Plan Owner + exercise participants: accountable for rollback activation (not only discussion) during the exercise.
A45: E4 | C45: Exit Plan Owner + Operations Lead: jointly accountable for executing and confirming a partial migration test.

Sheet C5
A1: Control 5: Testing Programme and Periodic Evaluation
A2: Risk | C2: Exit plans and documentation that are created but never tested provide false assurance. Technology, provider terms, and organizational context change continuously. DICTU level 5 explicitly requires documentation that is 'tested'. Without periodic testing, the organization cannot demonstrate that its exit capability is real rather than theoretical.
A3: Objective | C3: Verify that exit capability is subject to a structured, periodic test programme, and that findings from testing result in documented, tracked remediation activities reported to senior management.
A4: Sovereignty link | C4: Technology Sovereignty (DICTU 3.4 level 5: 'sufficiently detailed AND TESTED') | EuroStack Criterion 2.3 (tested deployment capability) | ISO 22301 §8.5 (BCM test programme)
A6: Audit Questions
A7: # | C7: Audit Question | D7: Yes/No | E7: Notes
A8: 5.1 | C8: Does a documented exit capability test programme exist, specifying: test types (tabletop, data export test, partial migration), test frequency (minimum annual for critical services), responsible parties, scope, and success criteria?
A9: 5.2 | C9: Has an annual tabletop exercise specifically testing exit scenarios been conducted, attended by IT, Legal, Compliance, and senior management, with a scenario that includes at least one unplanned exit trigger (provider insolvency, geopolitical sanctions, or non-EU acquisition)?
A10: 5.3 | C10: Has a complete or representative data export test, including import validation in an alternative environment, been conducted within the past 24 months, with results documented including data integrity confirmation?
A11: 5.4 | C11: Is there a procedure for trigger-based review of the exit plan upon material changes (new service onboarded, contract renewal, major data volume increase, regulatory change, geopolitical development affecting the provider), and has at least one trigger-based review taken place in the past 24 months if triggers have occurred?
A12: 5.5 | C12: Is a findings register maintained for all exit-related testing, with named owners and due dates, and are findings reported to senior management or the Audit Committee at least annually?
A14: Part A: Design Maturity (M1–M5)
A15: Instructions: Tick (✓) the HIGHEST level at which ALL criteria are fully satisfied. Levels are CUMULATIVE.
A16: Level | C16: Definition | D16: Criteria (cumulative) | E16: Suggested Evidence to Provide | F16: Reached (✓) | G16: Notes
A17: M1 | B17: No Testing | C17: Service not transferable; continuity not guaranteed. | D17: 1. Exit capability has never been tested in any form. 2. No test programme exists. 3. No findings register maintained. | E17: → Absence of any test records confirms M1. If no evidence is produced, this level applies by default.
A18: M2 | B18: Ad Hoc Testing | C18: Documentation is limited; transfer to a third party is complex and not fully possible. | D18: 1. Cumulative: the organization has progressed beyond M1 (the M1 absence conditions no longer apply), PLUS: 2. Some informal testing or discussion of exit scenarios has occurred. 3. No structured programme, no documented findings, no remediation tracking. | E18: → Email records or meeting notes mentioning exit scenario discussion (note: informal discussion without documented outcomes confirms M2 at most).
A19: M3 | B19: Annual Tabletop | C19: Service largely transferable; high-level documentation available. | D19: 1. Cumulative: M2 satisfied, PLUS: 2. A formal test programme document exists specifying test types and frequency. 3. Annual tabletop exercise conducted within the past 12 months. 4. Tabletop scenario included at least one unplanned exit trigger. 5. Exercise findings are documented (data export test not yet conducted). | E19: → Test programme document with frequency and test types. → Tabletop exercise report: date, scenario, attendance list, findings. → Confirmation that scenario included an unplanned trigger (not only voluntary migration).
A20: M4 | B20: Full Test Programme | C20: Service fully transferable; documentation sufficiently detailed. | D20: 1. Cumulative: M3 satisfied, PLUS: 2. Data export test conducted within 24 months with import validation. 3. Test findings tracked in findings register with owners and due dates. 4. Findings reported to senior management at least annually. 5. Trigger-based review procedure in place. | E20: → Data export test report with import validation evidence. → Findings register showing open and closed items from all test types. → Management report or Audit Committee minutes referencing exit capability test results. → Trigger-based review procedure document.
A21: M5 | B21: Comprehensively Tested | C21: Service fully transferable; documentation sufficiently detailed and tested. | D21: 1. Cumulative: M4 satisfied, PLUS: 2. Partial migration test (or equivalent highest-level exercise) conducted in addition to tabletop and export test. 3. Test programme subject to independent oversight (internal audit or external review). 4. All prior-period findings are closed or have an accepted risk. | E21: → Partial migration test report or equivalent live exercise evidence. → Independent oversight record (internal audit scope or external review engagement). → Findings register showing all prior-period items closed or risk-accepted with approval.
A22: DESIGN MATURITY CONCLUSION | C22: Maturity Level Assigned: | D22: {=IFERROR(LOOKUP(2,1/(F17:F21<>""),{1;2;3;4;5}),"")} | E22: Rationale / Finding:
A24: Part B: Operational Effectiveness (E1–E4)
A25: Instructions: Assess whether the designed control operated as intended during the audit period.
A26: Level | C26: What the Organization Must Demonstrate | D26: Audit Procedure | E26: Audit Guidance | F26: Reached (✓) | G26: Notes
A27: E1 | B27: Not Effective | C27: 1. No evidence of any exit-related testing in the past 24 months. 2. No test programme document. 3. No findings register. | D27: 1. Request test records for exit scenarios over 24 months. 2. If none produced, rate E1. 3. Verify whether test programme document exists. | E27: If no testing has been conducted in the past 24 months, E1 applies regardless of how the design maturity is scored.
A28: E2 | B28: Partially Effective | C28: 1. Annual tabletop conducted. 2. Findings documented. 3. Remediation incomplete or data export test not yet conducted. | D28: 1. Review most recent tabletop report: date, scenario, participants, findings. 2. Check findings register for open items. 3. Verify data export test status. | E28: Confirm the tabletop scenario included an unplanned trigger. A planned migration session labelled as a tabletop exercise does not meet this requirement.
A29: E3 | B29: Largely Effective | C29: 1. Tabletop and data export test completed within 24 months. 2. All findings from both tests closed. 3. Annual management reporting evidenced. | D29: 1. Review data export test results including import validation. 2. Confirm all tabletop and export test findings are addressed. 3. Review management report or Audit Committee minutes. | E29: E3 requires both test types: tabletop for governance and decision-making, and data export test for technical validation. One without the other is E2 at most.
A30: E4 | B30: Fully Effective | C30: 1. Full programme: tabletop, export test, and partial migration test. 2. Independent oversight of test programme. 3. All prior findings closed. | D30: 1. Review partial migration test documentation. 2. Confirm independent oversight (internal audit scope or external review). 3. Verify all prior-period findings are closed. | E30: E4 requires a partial migration test and independent oversight. An organization that has never tested an actual migration cannot claim E4 regardless of how thorough its tabletop exercises are.
A31: EFFECTIVENESS CONCLUSION | C31: Effectiveness Level Assigned: | D31: {=IFERROR(LOOKUP(2,1/(F27:F30<>""),{1;2;3;4}),"")} | E31: Rationale / Finding:
A33: Responsible Roles (Testing Programme and Periodic Evaluation)
A34: Design Maturity Level | C34: Responsible Role (typically accountable for evidence at this level)
A35: M1–M2 | C35: No test programme owner exists at this level. Escalate to CIO / Audit Committee to mandate a test programme.
A36: M3 | C36: Test Programme Owner: schedules and reports the annual tabletop exercise (with unplanned trigger) within the past 12 months.
A37: M4 | C37: Test Programme Owner + Infrastructure Lead: Owner maintains the findings register and trigger-based review procedure; Infrastructure Lead delivers the data export test.
A38: M5 | C38: Test Programme Owner + Internal Audit: Internal Audit provides independent oversight of the full test programme (tabletop, export test, partial migration).
